Workbook

Sheet temps généraux
B5: Pièce | C5: Phase | D5: Dénomination | E5: Machine | F5: Responsable 2.3 | G5: Responsable 2.4 | H5: nb de pièce (en entrée) | I5: La charge (min) | J5: Taux charge (Tr/1080) du poste | K5: Temps cycle eff (min) | L5: Top (min) | M5: responsable usinage | N5: informations supp (ne modifier rien sur cette colonne)
A6: 1 | B6: Support | C6: 10 | D6: Fraisage conv | E6: Fr 12 | F6: COURAU | G6: OUALI | H6: 31 | I6: 196.84 | J6: =I6/1080 -> 0.18225926 | K6: 6.258 | L6: 4.32 | M6: E.SANCHEZ
A7: 1 | B7: Support | C7: 15 | D7: Fraisage conv | E7: Fraiseuse | F7: DENISART | G7: BABA | H7: 30 | I7: 197.6 | J7: =I7/1080 -> 0.18296296 | K7: 11.5 | L7: 6.6 | M7: COURAU
A8: 1 | B8: Support | C8: 20 | D8: Fraisage conv | E8: Fraiseuse | F8: KAWTARI | G8: LEONE GOMEZ | H8: 25 | I8: 208.19 | J8: =I8/1080 -> 0.19276852 | K8: 8.66 | L8: 5.52 | M8: NOCHE | N8: calcules pur une piece. usinage pour 4 en mm temps
A9: 1 | B9: Support | C9: 30 | D9: Fraisage CN | E9: Romi (uinages simultanés) | F9: BENIC | G9: ROGER | H9: 22 | I9: 384 | J9: =I9/1080 -> 0.35555556 | K9: 10.95 | L9: 15.5 | M9: ZEFIZEF | N9: Tcyeff ne comprend pas la préparation machine, le temps requis et le Top oui.
B10: Equerre | C10: 20 | F10: BENIC | G10: ROGER | H10: 19 | K10: 8.75
A11: 1 | B11: Support | C11: 40 | D11: Fraisage CN | E11: HAAS (uinages simultanés) | F11: NOCHE | G11: ZEFIZEF | H11: 22 | I11: 451 | J11: =I11/1080 -> 0.41759259 | K11: 20.5 | L11: 13.54 | M11: MORIN | N11: Usinage par lot de pièce Les Tcyeff et Top ne comprennent pas la préparation machine, le temps requis oui.
B12: Equerre | C12: 30 | F12: NOCHE | G12: ZEFIZEF | H12: 19
B13: Support | C13: 50 | D13: Fraisage CN | E13: C2 | F13: SIDHOM | G13: COURAU | H13: 19 | I13: 144.4 | J13: =I13/1080 -> 0.1337037 | K13: 7.4 | L13: 3.86
B14: Support | C14: 60 | D14: Taraudage | E14: Taraudeuse | F14: - | G14: MORIN | H14: 19 | I14: 163.76 | J14: =I14/1080 -> 0.15162963 | K14: 7.04 | L14: 4.75
A15: 2 | B15: Equerre | C15: 0 | D15: Découpage | E15: Jet d'eau | F15: - | G15: BABA | H15: 23 | I15: 227.86 | J15: =I15/1080 -> 0.21098148 | K15: 15.6 | L15: 10 | M15: ROGER/OZMEN
B16: Equerre | C16: 10 | D16: Fraisage conv | E16: Fraiseuse | F16: DAUDET | G16: - | N16: ne pas faire
B17: Equerre | C17: 40 | D17: Taraudage | E17: Taraudeuse | F17: - | G17: MORIN | H17: 19 | I17: 67 | J17: =I17/1080 -> 0.062037037 | K17: 2.25 | L17: 3
A18: 2 | B18: Palier | C18: 10 | D18: Tournage CN | E18: CTX 200 | F18: ZEFIZEF | G18: NOCHE | H18: 48 | I18: =48*K18 -> 840 | J18: =I18/1080 -> 0.77777778 | K18: 17.5 | L18: 14.1 | M18: LEONE--GOMEZ / TREHEUX
B19: Palier | C19: 20 | D19: Fraisage conv | E19: Fraiseuse | F19: BABA | G19: DENISART TEPER | H19: 40 | I19: 377 | J19: =I19/1080 -> 0.34907407 | K19: 9.42 | L19: 6.71
A20: 1 | B20: Cylindre | C20: 10 | D20: Tournage conv | E20: Tour | F20: OUALI | G20: OZMEN | H20: 40 | I20: 223.41 | J20: =I20/1080 -> 0.20686111 | K20: 5.58 | L20: 4.18 | M20: SIDHOM
A21: 1 | B21: Cylindre | C21: 20 | D21: Tournage conv | E21: Tour | F21: MORIN | G21: KAWTARI | H21: 40 | I21: 410.63 | J21: =I21/1080 -> 0.38021296 | K21: 10.27 | L21: 5.77 | M21: KAWTARI
A22: 1 | B22: Cylindre | C22: 30 | D22: Fraisage CN | E22: Haas | F22: ELMOURABIT | G22: BOUZIDENE | H22: 40 | I22: 1068 | J22: =I22/1080 -> 0.98888889 | K22: 24.45 | L22: 17.42 | M22: CARDINALE | N22: pour le contrôle utiliser la métrios pour toute les côtes
A23: 2 | B23: Volant | C23: 0 | D23: Moulage | E23: Moulage | F23: - | G23: OUALI | H23: 26 | I23: 246 | J23: =I23/1080 -> 0.22777778 | K23: 12.03 | L23: 6 | M23: E.OUALI - DENISART
B24: Volant | C24: 10 | D24: Parachèvement | E24: Scie à ruban | F24: - | G24: ELMOURABIT | H24: 24 | I24: 46.08 | J24: =I24/1080 -> 0.042666667 | K24: 0.67 | L24: 0.67
A25: 1 | B25: Volant | C25: 20 | D25: Tournage conv | E25: Tour | F25: LEONE GOMEZ | G25: ELMOURABIT | H25: 24 | I25: 289.2 | J25: =I25/1080 -> 0.26777778 | K25: 4.5 | L25: 4.59 | M25: DAUDET
A26: 1 | B26: Volant | C26: 30 | D26: Tournage conv | E26: Tour | F26: SANCHEZ | G26: DAUDET | H26: 20 | I26: 385.2 | J26: =I26/1080 -> 0.35666667 | K26: 19.26 | L26: 13.47 | M26: BENIC
B27: Volant | C27: 40 | D27: Tournage conv | E27: Tour | F27: SANCHEZ | G27: MORIN | H27: 19 | I27: 136 | J27: =I27/1080 -> 0.12592593 | K27: 4 | L27: 3.5
A28: 1 | B28: Piston | C28: 20 | D28: Tournage conv | E28: Mini tour | F28: BOUZIDENE | G28: SIDHOM | H28: 72 | I28: 482.4 | J28: =I28/1080 -> 0.44666667 | K28: 6.7 | L28: 5 | M28: ELMOURABIT
A29: 1 | B29: Piston | C29: 30 | D29: Tournage conv | E29: Tour | F29: BOUZIDENE | G29: SIDHOM | H29: 72 | I29: 452.8 | J29: =I29/1080 -> 0.41925926 | K29: 6.29 | L29: 4.72 | M29: BOUZIDENE
A30: 1 | B30: Piston | C30: 40 | D30: Tournage conv | E30: Tour | F30: CARDINALE | G30: BENIC | H30: 64 | I30: 757.8 | J30: =I30/1080 -> 0.70166667 | K30: 11.84 | L30: 7.99 | M30: BABA
B31: Piston | C31: 50 | D31: Pliage | E31: Plieuse | F31: - | G31: DENISART TEPER | H31: 57 | I31: 421 | J31: =I31/1080 -> 0.38981481 | K31: 4.1 | L31: 3.04
B32: Raccord M8 | C32: 10 | D32: Tournage CN | E32: GL 250 | F32: TREHEUX | G32: CARDINALE | H32: 23 | I32: 405.2 | J32: =I32/1080 -> 0.37518519 | K32: 12.4 | L32: 7.51
B33: Raccord M8 | C33: 20 | D33: Tournage CN | E33: CTX200 | F33: OZMEN | G33: SANCHEZ SARTORI | H33: 20 | I33: 450 | J33: =I33/1080 -> 0.41666667 | K33: 11.25 | L33: 7.22
B34: Pied | C34: 10 | D34: Tournage CN | E34: TBI 280 | F34: ROGER | G34: TREHEUX | H34: 76 | I34: =120+(431.4378817/60) -> 127.19063 | J34: =I34/1080 -> 0.1177691 | K34: 7.3858889 | L34: 5.5394167
B89: Pièce | C89: Phase | D89: Dénomination | E89: Machine | F89: Responsable 2.3 | G89: Responsable 2.4 | H89: nb de pièce | I89: Temps requis (min) | J89: Taux charge (Tr/1080) du poste | K89: Temps cycle eff (min) | L89: Top (min) | M89: responsable usinage | N89: informations supp
B90: Piston | C90: 40 | D90: Tournage conv | E90: Tour | F90: AGRIGNAN | G90: MANSOUR | H90: 69 | I90: 698.97 | J90: =I90/1080 -> 0.64719444 | K90: 10.13 | L90: 8.13 | M90: MARZOUKI
B94: Phase | C94: Opérateur | D94: nb de pièces à faire | E94: nb pièces réalisées | F94: rebuts | G94: taux de qualité | H94: taux de qualité h-1 | I94: temps cycle moyen | J94: temps requis pour finir l'usinage | L94: % pi réalisées
B95: 40 | C95: Marzouki | D95: 69 | E95: 88 | F95: 16 | G95: 0.8182 | H95: 0.78 | I95: 0.0076157407 | J95: =(D95-E95)*I95 -> -0.14469907 | K95: =IF(J95>=$C$40,"retard","ok") -> ok | L95: =E95/D95 -> 1.2753623

Sheet Feuille suivi général
B2: temps réstant : | C2: =C40 -> 0.58333333
B4: Pièce | C4: Phase | D4: Opérateur | E4: nb de pièces à faire | F4: nb pièces réalisées | G4: rebuts | H4: taux de qualité | I4: taux de qualité h-1 | J4: temps cycle moyen | K4: temps requis pour finir l'usinage | M4: % pi réalisées
B5: Support | C5: 10 | D5: E.SANCHEZ | E5: 31 | F5: ='Support ph10'!L17 -> 3 | G5: ='Support ph10'!M17 -> 1 | H5: ='Support ph10'!O17 -> 0.66666667 | I5: 1 | J5: ='Support ph10'!P17 -> 0.0076388889 | K5: =(E5-F5)*J5 -> 0.21388889 | L5: =IF(K5>=$C$40,"retard","ok") -> ok | M5: =F5/E5 -> 0.096774194
C6: 15 | D6: COURAU | E6: 26 | F6: ='Support ph15'!J17 -> 7 | G6: ='Support ph15'!K17 -> 0 | H6: ='Support ph15'!M17 -> 1 | I6: 1 | J6: ='Support ph15'!N17 -> 0.0050595238 | K6: =(E6-F6)*J6 -> 0.096130952 | L6: =IF(K6>=$C$40,"retard","ok") -> ok | M6: =F6/E6 -> 0.26923077
C7: 20 | D7: NOCHE | E7: 22 | F7: ='Support ph20'!M7 -> 4 | G7: ='Support ph20'!N7 -> 0 | H7: ='Support ph20'!P7 -> 1 | I7: 0.96 | J7: ='Support ph20'!Q7 -> 0.010416667 | K7: =(E7-F7)*J7 -> 0.1875 | L7: =IF(K7>=$C$40,"retard","ok") -> ok | M7: =F7/E7 -> 0.18181818
C8: 30 | D8: ZEFIZEF | E8: 22 | F8: ='Support ph30'!L16 -> 0 | G8: ='Support ph30'!M16 -> 0 | H8: ='Support ph30'!O16 -> #DIV/0! | I8: 0.88888889 | J8: ='Support ph30'!P16 -> #DIV/0! | K8: =(E8-F8)*J8 -> #DIV/0! | L8: =IF(K8>=$C$40,"retard","ok") -> #DIV/0! | M8: =F8/E8 -> 0
B9: Equerre | C9: 20 | E9: 19 | F9: ='Equerre ph20'!L17 -> 0 | G9: ='Equerre ph20'!M17 -> 0 | H9: ='Equerre ph20'!O17 -> #DIV/0! | I9: 0.96 | J9: ='Equerre ph20'!P17 -> #DIV/0! | K9: =(E9-F9)*J9 -> #DIV/0! | L9: =IF(K9>=$C$40,"retard","ok") -> #DIV/0! | M9: =F9/E9 -> 0
B10: Support | C10: 40 | D10: MORIN | E10: 19 | F10: ='Support ph40'!L17 -> 0 | G10: ='Support ph40'!M17 -> 0 | H10: ='Support ph40'!O17 -> #DIV/0! | I10: 0.83333333 | J10: ='Support ph40'!P17 -> #DIV/0! | K10: =(E10-F10)*J10 -> #DIV/0! | L10: =IF(K10>=$C$40,"retard","ok") -> #DIV/0! | M10: =F10/E10 -> 0
B11: Equerre | C11: 30 | E11: 19 | F11: ='Equerre ph30'!L17 -> 0 | G11: ='Equerre ph30'!M17 -> 0 | H11: ='Equerre ph30'!O17 -> #DIV/0! | I11: 0.83333333 | J11: ='Equerre ph30'!P17 -> #DIV/0! | K11: =(E11-F11)*J11 -> #DIV/0! | L11: =IF(K11>=$C$40,"retard","ok") -> #DIV/0! | M11: =F11/E11 -> 0
B12: Support | C12: 50 | E12: 19 | F12: ='Support ph50'!L17 -> 0 | G12: ='Support ph50'!M17 -> 0 | H12: ='Support ph50'!O17 -> #DIV/0! | I12: 1 | J12: ='Support ph50'!P17 -> #DIV/0! | K12: =(E12-F12)*J12 -> #DIV/0! | L12: =IF(K12>=$C$40,"retard","ok") -> #DIV/0! | M12: =F12/E12 -> 0
C13: 60 | D13: Dernières séances | E13: 19 | F13: ='Support ph60'!L17 -> 0 | G13: ='Support ph60'!M17 -> 0 | H13: ='Support ph60'!O17 -> #DIV/0! | I13: 0.9 | J13: ='Support ph60'!P17 -> #DIV/0! | K13: =(E13-F13)*J13 -> #DIV/0! | L13: =IF(K13>=$C$40,"retard","ok") -> #DIV/0! | M13: =F13/E13 -> 0
B14: Equerre | C14: 0 | E14: 22 | F14: ='Equerre ph0'!L11 -> 24 | G14: ='Equerre ph0'!M11 -> 0 | H14: ='Equerre ph0'!O11 -> 1 | I14: 0.77272727 | J14: ='Equerre ph0'!P11 -> 0.0035011574 | K14: =(E14-F14)*J14 -> -0.0070023148 | L14: =IF(K14>=$C$40,"retard","ok") -> ok | M14: =F14/E14 -> 1.0909091
C15: 10 | D15: Non réalisé | F15: Non réalisé
C16: 40 | D16: Dernières séances | E16: 19 | F16: ='Equerre ph40'!L17 -> 0 | G16: ='Equerre ph40'!M17 -> 0 | H16: ='Equerre ph40'!O17 -> #DIV/0! | I16: 1 | J16: ='Equerre ph40'!P17 -> #DIV/0! | K16: =(E16-F16)*J16 -> #DIV/0! | L16: =IF(K16>=$C$40,"retard","ok") -> #DIV/0! | M16: =F16/E16 -> 0
B17: Palier | C17: 10 | D17: LEONE--GOMEZ / TREHEUX | E17: 40 | F17: ='Palier ph10'!M17 -> 7 | G17: ='Palier ph10'!N17 -> 7 | H17: ='Palier ph10'!P17 -> 0 | I17: 0.72131148 | J17: ='Palier ph10'!Q17 -> 0.0055555556 | K17: =(E17-F17)*J17 -> 0.18333333 | L17: =IF(K17>=$C$40,"retard","ok") -> ok | M17: =F17/E17 -> 0.175
C18: 20 | E18: 38 | F18: ='Palier ph20'!L17 -> 0 | G18: ='Palier ph20'!M17 -> 0 | H18: ='Palier ph20'!O17 -> #DIV/0! | I18: 1 | J18: ='Palier ph20'!P17 -> #DIV/0! | K18: =(E18-F18)*J18 -> #DIV/0! | L18: =IF(K18>=$C$40,"retard","ok") -> #DIV/0! | M18: =F18/E18 -> 0
B19: Cylindre | C19: 10 | D19: SIDHOM | E19: 40 | F19: ='Cylindre ph10'!L17 -> 0 | G19: ='Cylindre ph10'!M17 -> 0 | H19: ='Cylindre ph10'!O17 -> #DIV/0! | I19: 1 | J19: ='Cylindre ph10'!P17 -> #DIV/0! | K19: =(E19-F19)*J19 -> #DIV/0! | L19: =IF(K19>=$C$40,"retard","ok") -> #DIV/0! | M19: =F19/E19 -> 0
C20: 20 | D20: KAWTARI | E20: 40 | F20: ='Cylindre ph20'!L17 -> 0 | G20: ='Cylindre ph20'!M17 -> 0 | H20: ='Cylindre ph20'!O17 -> #DIV/0! | I20: 0.97727273 | J20: ='Cylindre ph20'!P17 -> #DIV/0! | K20: =(E20-F20)*J20 -> #DIV/0! | L20: =IF(K20>=$C$40,"retard","ok") -> #DIV/0! | M20: =F20/E20 -> 0
C21: 30 | D21: CARDINALE | E21: 38 | F21: ='Cylindre ph30'!M17 -> 0 | G21: ='Cylindre ph30'!N17 -> 0 | H21: ='Cylindre ph30'!P17 -> #DIV/0! | I21: 1 | J21: ='Cylindre ph30'!Q17 -> #DIV/0! | K21: =(E21-F21)*J21 -> #DIV/0! | L21: =IF(K21>=$C$40,"retard","ok") -> #DIV/0! | M21: =F21/E21 -> 0
B22: Volant | C22: 0 | D22: E.OUALI - DENISART | E22: 24 | F22: ='Volant ph0'!L17 -> 0 | G22: ='Volant ph0'!M17 -> 0 | H22: ='Volant ph0'!O17 -> #DIV/0! | I22: 0.75 | J22: ='Volant ph0'!P17 -> #DIV/0! | K22: =(E22-F22)*J22 -> #DIV/0! | L22: =IF(K22>=$C$40,"retard","ok") -> #DIV/0! | M22: =F22/E22 -> 0
C23: 10 | E23: 24 | F23: ='Volant ph10'!L17 -> 0 | G23: ='Volant ph10'!M17 -> 0 | H23: ='Volant ph10'!O17 -> #DIV/0! | I23: 1 | J23: ='Volant ph10'!P17 -> #DIV/0! | K23: =(E23-F23)*J23 -> #DIV/0! | L23: =IF(K23>=$C$40,"retard","ok") -> #DIV/0! | M23: =F23/E23 -> 0
C24: 20 | D24: DAUDET | E24: 20 | F24: ='Volant ph20'!M17 -> 2 | G24: ='Volant ph20'!N17 -> 1 | H24: ='Volant ph20'!P17 -> 0.5 | I24: 0.7826087 | J24: ='Volant ph20'!Q17 -> 0.034027778 | K24: =(E24-F24)*J24 -> 0.6125 | L24: =IF(K24>=$C$40,"retard","ok") -> retard | M24: =F24/E24 -> 0.1
C25: 30 | D25: BENIC | E25: 19 | F25: ='Volant ph30'!L17 -> 1 | G25: ='Volant ph30'!M17 -> 0 | H25: ='Volant ph30'!O17 -> 1 | I25: 0.95652174 | J25: ='Volant ph30'!P17 -> 0.055555556 | K25: =(E25-F25)*J25 -> 1 | L25: =IF(K25>=$C$40,"retard","ok") -> retard | M25: =F25/E25 -> 0.052631579
C26: 40 | E26: 19 | F26: ='Volant ph40'!L16 -> 0 | G26: ='Volant ph40'!M16 -> 0 | H26: ='Volant ph40'!O16 -> #DIV/0! | I26: 1 | J26: ='Volant ph40'!P16 -> #DIV/0! | K26: =(E26-F26)*J26 -> #DIV/0! | L26: =IF(K26>=$C$40,"retard","ok") -> #DIV/0! | M26: =F26/E26 -> 0
B27: Piston | C27: 20 | D27: ELMOURABIT | E27: 72 | F27: ='Piston ph20'!L17 -> 20 | G27: ='Piston ph20'!M17 -> 0 | H27: ='Piston ph20'!O17 -> 1 | I27: 1 | J27: ='Piston ph20'!P17 -> 0.0049010417 | K27: =(E27-F27)*J27 -> 0.25485417 | L27: =IF(K27>=$C$40,"retard","ok") -> ok | M27: =F27/E27 -> 0.27777778
C28: 30 | D28: BOUZIDENE | E28: 64 | F28: ='Piston ph30'!L17 -> 2 | G28: ='Piston ph30'!M17 -> 1 | H28: ='Piston ph30'!O17 -> 0.5 | I28: 0.79104478 | J28: ='Piston ph30'!P17 -> -0.0038040123 | K28: =(E28-F28)*J28 -> -0.23584877 | L28: =IF(K28>=$C$40,"retard","ok") -> ok | M28: =F28/E28 -> 0.03125
C29: 40 | D29: BABA | E29: 57 | F29: ='Piston ph40'!L17 -> 0 | G29: ='Piston ph40'!M17 -> 0 | H29: ='Piston ph40'!O17 -> #DIV/0! | I29: 0.78 | J29: ='Piston ph40'!P17 -> #DIV/0! | K29: =(E29-F29)*J29 -> #DIV/0! | L29: =IF(K29>=$C$40,"retard","ok") -> #DIV/0! | M29: =F29/E29 -> 0
C30: 50 | D30: Dernières séances | E30: 57 | F30: ='Piston ph50'!L17 -> 0 | G30: ='Piston ph50'!M17 -> 0 | H30: ='Piston ph50'!O17 -> #DIV/0! | I30: 1 | J30: ='Piston ph50'!P17 -> #DIV/0! | K30: =(E30-F30)*J30 -> #DIV/0! | L30: =IF(K30>=$C$40,"retard","ok") -> #DIV/0! | M30: =F30/E30 -> 0
B31: Raccord M8 | C31: 10 | E31: 23 | F31: ='Raccord M8 ph10'!R17 -> 0 | G31: ='Raccord M8 ph10'!S17 -> 0 | H31: ='Raccord M8 ph10'!U17 -> #DIV/0! | I31: 0.97777778 | J31: ='Raccord M8 ph10'!V17 -> #DIV/0! | K31: =(E31-F31)*J31 -> #DIV/0! | L31: =IF(K31>=$C$40,"retard","ok") -> #DIV/0! | M31: =F31/E31 -> 0
C32: 20 | D32: Après 1ere séance | E32: 19 | F32: ='Raccord M8 ph20'!L17 -> 0 | G32: ='Raccord M8 ph20'!M17 -> 0 | H32: ='Raccord M8 ph20'!O17 -> #DIV/0! | I32: 1 | J32: ='Raccord M8 ph20'!P17 -> #DIV/0! | K32: =(E32-F32)*J32 -> #DIV/0! | L32: =IF(K32>=$C$40,"retard","ok") -> #DIV/0! | M32: =F32/E32 -> 0
B33: Pied | C33: 10 | E33: =19*3 -> 57 | F33: ='Pied ph10'!L17 -> 0 | G33: ='Pied ph10'!M17 -> 0 | H33: ='Pied ph10'!O17 -> #DIV/0! | I33: 0.97727273 | J33: ='Pied ph10'!P17 -> #DIV/0! | K33: =(E33-F33)*J33 -> #DIV/0! | L33: =IF(K33>=$C$40,"retard","ok") -> #DIV/0! | M33: =F33/E33 -> 0
C35: Séance 1 | D35: Séance 2 | E35: Séance 3 | F35: Séance 4 | G35: Séance 5 | J35: Nombre de moteurs réalisés
B36: Heure du jour / Fin | C36: 0.72916667 | D36: 0 | E36: 0 | F36: 0 | G36: 0 | J36: ='total moteurs'!G8 -> 0 | K36: /19
B37: Lancement séance | C37: 0.5625 | D37: 0 | E37: 0 | F37: 0 | G37: 0
B38: temps disponible | C38: 0.75
B39: temps écoulé | C39: =C36-C37 -> 0.16666667 | D39: =D36-D37 -> 0 | E39: =E36-E37 -> 0 | F39: =F36-F37 -> 0 | G39: =G36-G37 -> 0
B40: temps réstant | C40: =C38-SUM(C39:G39) -> 0.58333333

Sheet total moteurs
B4: Pièce | C4: quantité produite | D4: nb par moteurs | E4: lots produits
A5: Phase finale pdt dernières séances | B5: Support | C5: ='Support ph60'!L5 -> 0 | D5: 1 | E5: =ROUNDDOWN(C5/D5,0) -> 0
A6: Phase finale pdt dernières séances | B6: Equerre | C6: ='Equerre ph40'!L5 -> 0 | D6: 1 | E6: =ROUNDDOWN(C6/D6,0) -> 0
B7: Palier | C7: ='Palier ph20'!L5 -> 0 | D7: 2 | E7: =ROUNDDOWN(C7/D7,0) -> 0 | G7: Nombre de moteur réalisés
B8: Cylindre | C8: ='Cylindre ph30'!M6 -> 0 | D8: 2 | E8: =ROUNDDOWN(C8/D8,0) -> 0 | G8: =MIN(E5:E12) -> 0 | H8: /19
B9: Volant | C9: ='Volant ph40'!L5 -> 0 | D9: 1 | E9: =ROUNDDOWN(C9/D9,0) -> 0
A10: Phase finale pdt dernières séances | B10: Piston | C10: ='Piston ph50'!L7 -> 0 | D10: 3 | E10: =ROUNDDOWN(C10/D10,0) -> 0
B11: Raccord M8 | C11: ='Raccord M8 ph20'!L5 -> 0 | D11: 2 | E11: =ROUNDDOWN(C11/D11,0) -> 0
B12: Pied | C12: ='Pied ph10'!L5 -> 0 | D12: 4 | E12: =ROUNDDOWN(C12/D12,0) -> 0

Sheet Feuille suivi Séance 1

Sheet Feuille suivi Séance 2

Sheet Feuille suivi Séance 3

Sheet Feuille suivi Séance 4

Sheet Feuille suivi Séance 5

Sheet Equerre ph0
A1: fiche de suivie de production Pièce : Equerre Phase :0
A3: N° | B3: date | C3: opérateur | D3: heure début usinage | E3: heure fin usinage | F3: Conformité | G3: cote 1 | H3: cote 2 | I3: cote 3 | J3: temps de cycle
A5: 1 | B5: 46119 | C5: ROGER/OSMEN | D5: 0.52777778 | E5: 0.53125 | F5: OUI | J5: =E5-D5 -> 0.0034722222
A6: 2 | B6: 46119 | C6: ROGER/OSMEN | D6: 0.53125 | E6: 0.53472222 | F6: OUI | J6: =E6-D6 -> 0.0034722222
A7: 3 | B7: 46119 | C7: ROGER/OSMEN | D7: 0.53472222 | E7: 0.53819444 | F7: OUI | J7: =E7-D7 -> 0.0034722222
A8: 4 | B8: 46119 | C8: ROGER/OSMEN | D8: 0.53819444 | E8: 0.54166667 | F8: OUI | J8: =E8-D8 -> 0.0034722222
A9: 5 | B9: 46119 | C9: ROGER/OSMEN | D9: 0.54166667 | E9: 0.54513889 | F9: OUI | J9: =E9-D9 -> 0.0034722222
A10: 6 | B10: 46119 | C10: ROGER/OSMEN | D10: 0.54513889 | E10: 0.54861111 | F10: OUI | J10: =E10-D10 -> 0.0034722222 | L10: Nb pièce produite (fausse et bonne) | M10: Nombre piéce fausse | N10: nombre piéce bonne | O10: taux qualité | P10: Tcy moyen
A11: 7 | B11: 46119 | C11: ROGER/OZMEN | D11: 0.54861111 | E11: 0.55208333 | F11: OUI | J11: =E11-D11 -> 0.0034722222 | L11: =COUNTA(F5:F92) -> 24 | M11: =COUNTIF(F5:F93,"non") -> 0 | N11: =COUNTIF(F5:F92,"oui") -> 24 | O11: =(L11-M11)/L11 -> 1 | P11: =AVERAGEIF(J$5:J$200,"<>0") -> 0.0035011574
A12: 8 | B12: 46119 | C12: ROGER/OZMEN | D12: 0.55208333 | E12: 0.55555556 | F12: OUI | J12: =E12-D12 -> 0.0034722222
A13: 9 | B13: 46119 | C13: ROGER/OZMEN | D13: 0.55555556 | E13: 0.55902778 | F13: OUI | J13: =E13-D13 -> 0.0034722222
A14: 10 | B14: 46119 | C14: ROGER/OZMEN | D14: 0.55902778 | E14: 0.5625 | F14: OUI | J14: =E14-D14 -> 0.0034722222
A15: 11 | B15: 46119 | C15: ROGER/OZMEN | D15: 0.5625 | E15: 0.56597222 | F15: OUI | J15: =E15-D15 -> 0.0034722222
A16: 12 | B16: 46119 | C16: ROGER/OZMEN | D16: 0.56597222 | E16: 0.56944444 | F16: OUI | J16: =E16-D16 -> 0.0034722222
A17: 13 | B17: 46119 | C17: ROGER/OZMEN | D17: 0.56944444 | E17: 0.57291667 | F17: OUI | J17: =E17-D17 -> 0.0034722222
A18: 14 | B18: 46119 | C18: ROGER/OZMEN | D18: 0.57291667 | E18: 0.57638889 | F18: OUI | J18: =E18-D18 -> 0.0034722222
A19: 15 | B19: 46119 | C19: ROGER/OZMEN | D19: 0.57638889 | E19: 0.57986111 | F19: OUI | J19: =E19-D19 -> 0.0034722222
A20: 16 | B20: 46119 | C20: ROGER/OZMEN | D20: 0.57986111 | E20: 0.58333333 | F20: OUI | J20: =E20-D20 -> 0.0034722222
A21: 17 | B21: 46119 | C21: ROGER/OZMEN | D21: 0.58333333 | E21: 0.58680556 | F21: OUI | J21: =E21-D21 -> 0.0034722222
A22: 18 | B22: 46119 | C22: ROGER/OZMEN | D22: 0.58680556 | E22: 0.59027778 | F22: OUI | J22: =E22-D22 -> 0.0034722222
A23: 19 | B23: 46119 | C23: ROGER/OZMEN | D23: 0.59027778 | E23: 0.59375 | F23: OUI | J23: =E23-D23 -> 0.0034722222
... A28: 24 | B28: 46119 | C28: ROGER/OZMEN | D28: 0.65416667 | E28: 0.65763889 | F28: OUI | J28: =E28-D28 -> 0.0034722222
A29: 25 | D29: 0 | E29: 0 | J29: =E29-D29 -> 0
A30: 26 | D30: 0 | E30: 0 | J30: =E30-D30 -> 0
A31: 27 | D31: 0 | E31: 0 | J31: =E31-D31 -> 0
A32: 28 | D32: 0 | E32: 0 | J32: =E32-D32 -> 0
A33: 29 | D33: 0 | E33: 0 | J33: =E33-D33 -> 0
A34: 30 | D34: 0 | E34: 0 | J34: =E34-D34 -> 0
A35: 31 | D35: 0 | E35: 0 | J35: =E35-D35 -> 0
A36: 32 | D36: 0 | E36: 0 | J36: =E36-D36 -> 0
A37: 33 | D37: 0 | E37: 0 | J37: =E37-D37 -> 0
A38: 34 | D38: 0 | E38: 0 | J38: =E38-D38 -> 0
A39: 35 | D39: 0 | E39: 0 | J39: =E39-D39 -> 0
A40: 36 | D40: 0 | E40: 0 | J40: =E40-D40 -> 0
... A81: 77 | D81: 0 | E81: 0 | J81: =E81-D81 -> 0

Sheet Equerre ph10
A1: fiche de suivie de production Pièce : Equerre Phase :10
A3: N° | B3: date | C3: opérateur | D3: heure début usinage | E3: heure fin usinage | F3: Conformité | G3: cote 1 | H3: cote 2 | I3: cote 3 | J3: temps de cycle
A5: 1 | D5: 0 | E5: 0 | J5: =E5-D5 -> 0
A6: 2 | D6: 0 | E6: 0 | J6: =E6-D6 -> 0
A7: 3 | D7: 0 | E7: 0 | J7: =E7-D7 -> 0
A8: 4 | D8: 0 | E8: 0 | J8: =E8-D8 -> 0
A9: 5 | D9: 0 | E9: 0 | J9: =E9-D9 -> 0
A10: 6 | D10: 0 | E10: 0 | J10: =E10-D10 -> 0
A11: 7 | D11: 0 | E11: 0 | J11: =E11-D11 -> 0
A12: 8 | D12: 0 | E12: 0 | J12: =E12-D12 -> 0
A13: 9 | D13: 0 | E13: 0 | J13: =E13-D13 -> 0
A14: 10 | D14: 0 | E14: 0 | J14: =E14-D14 -> 0
A15: 11 | D15: 0 | E15: 0 | J15: =E15-D15 -> 0
A16: 12 | D16: 0 | E16: 0 | J16: =E16-D16 -> 0 | L16: Nb pièce produite (fausse et bonne) | M16: Nombre piéce fausse | N16: nombre piéce bonne | O16: taux qualité | P16: Tcy moyen
A17: 13 | D17: 0 | E17: 0 | J17: =E17-D17 -> 0 | L17: =COUNTA(F5:F92) -> 0 | M17: =COUNTIF(F5:F93,"non") -> 0 | N17: =COUNTIF(F5:F92,"oui") -> 0 | O17: =(L17-M17)/L17 -> #DIV/0! | P17: =AVERAGEIF(J$5:J$200,"<>0") -> #DIV/0!
A18: 14 | D18: 0 | E18: 0 | J18: =E18-D18 -> 0
A19: 15 | D19: 0 | E19: 0 | J19: =E19-D19 -> 0
A20: 16 | D20: 0 | E20: 0 | J20: =E20-D20 -> 0
A21: 17 | D21: 0 | E21: 0 | J21: =E21-D21 -> 0
A22: 18 | D22: 0 | E22: 0 | J22: =E22-D22 -> 0
A23: 19 | D23: 0 | E23: 0 | J23: =E23-D23 -> 0
A24: 20 | D24: 0 | E24: 0 | J24: =E24-D24 -> 0
A25: 21 | D25: 0 | E25: 0 | J25: =E25-D25 -> 0
A26: 22 | D26: 0 | E26: 0 | J26: =E26-D26 -> 0
A27: 23 | D27: 0 | E27: 0 | J27: =E27-D27 -> 0
A28: 24 | D28: 0 | E28: 0 | J28: =E28-D28 -> 0
A29: 25 | D29: 0 | E29: 0 | J29: =E29-D29 -> 0
... A81: 77 | D81: 0 | E81: 0 | J81: =E81-D81 -> 0

Sheet Equerre ph20
A1: fiche de suivie de production Pièce : Equerre Phase : 0
A3: N° | B3: date | C3: opérateur | D3: heure début usinage | E3: heure fin usinage | F3: Conformité | G3: cote 1 | H3: cote 2 | I3: cote 3 | J3: temps de cycle
A5: 1 | D5: 0 | E5: 0 | J5: =E5-D5 -> 0
A6: 2 | D6: 0 | E6: 0 | J6: =E6-D6 -> 0
A7: 3 | D7: 0 | E7: 0 | J7: =E7-D7 -> 0
A8: 4 | D8: 0 | E8: 0 | J8: =E8-D8 -> 0
A9: 5 | D9: 0 | E9: 0 | J9: =E9-D9 -> 0
A10: 6 | D10: 0 | E10: 0 | J10: =E10-D10 -> 0
A11: 7 | D11: 0 | E11: 0 | J11: =E11-D11 -> 0
A12: 8 | D12: 0 | E12: 0 | J12: =E12-D12 -> 0
A13: 9 | D13: 0 | E13: 0 | J13: =E13-D13 -> 0
A14: 10 | D14: 0 | E14: 0 | J14: =E14-D14 -> 0
A15: 11 | D15: 0 | E15: 0 | J15: =E15-D15 -> 0
A16: 12 | D16: 0 | E16: 0 | J16: =E16-D16 -> 0 | L16: Nb pièce produite (fausse et bonne) | M16: Nombre piéce fausse | N16: nombre piéce bonne | O16: taux qualité | P16: Tcy moyen
A17: 13 | D17: 0 | E17: 0 | J17: =E17-D17 -> 0 | L17: =COUNTA(F5:F92) -> 0 | M17: =COUNTIF(F5:F93,"non") -> 0 | N17: =COUNTIF(F5:F92,"oui") -> 0 | O17: =(L17-M17)/L17 -> #DIV/0! | P17: =AVERAGEIF(J$5:J$200,"<>0") -> #DIV/0!
A18: 14 | D18: 0 | E18: 0 | J18: =E18-D18 -> 0
A19: 15 | D19: 0 | E19: 0 | J19: =E19-D19 -> 0
A20: 16 | D20: 0 | E20: 0 | J20: =E20-D20 -> 0
A21: 17 | D21: 0 | E21: 0 | J21: =E21-D21 -> 0
A22: 18 | D22: 0 | E22: 0 | J22: =E22-D22 -> 0
A23: 19 | D23: 0 | E23: 0 | J23: =E23-D23 -> 0
A24: 20 | D24: 0 | E24: 0 | J24: =E24-D24 -> 0
A25: 21 | D25: 0 | E25: 0 | J25: =E25-D25 -> 0
A26: 22 | D26: 0 | E26: 0 | J26: =E26-D26 -> 0
A27: 23 | D27: 0 | E27: 0 | J27: =E27-D27 -> 0
A28: 24 | D28: 0 | E28: 0 | J28: =E28-D28 -> 0
A29: 25 | D29: 0 | E29: 0 | J29: =E29-D29 -> 0
... A81: 77 | D81: 0 | E81: 0 | J81: =E81-D81 -> 0

Sheet Equerre ph30
A1: fiche de suivie de production Pièce : Equerre Phase :30
A3: N° | B3: date | C3: opérateur | D3: heure début usinage | E3: heure fin usinage | F3: Conformité | G3: cote 1 | H3: cote 2 | I3: cote 3 | J3: temps de cycle
A5: 1 | C5: MORIN | D5: 0 | E5: 0 | J5: =E5-D5 -> 0
A6: 2 | C6: MORIN | D6: 0 | E6: 0 | J6: =E6-D6 -> 0
A7: 3 | C7: MORIN | D7: 0 | E7: 0 | J7: =E7-D7 -> 0
A8: 4 | C8: MORIN | D8: 0 | E8: 0 | J8: =E8-D8 -> 0
A9: 5 | C9: MORIN | D9: 0 | E9: 0 | J9: =E9-D9 -> 0
A10: 6 | C10: MORIN | D10: 0 | E10: 0 | J10: =E10-D10 -> 0
A11: 7 | C11: MORIN | D11: 0 | E11: 0 | J11: =E11-D11 -> 0
A12: 8 | C12: MORIN | D12: 0 | E12: 0 | J12: =E12-D12 -> 0
A13: 9 | C13: MORIN | D13: 0 | E13: 0 | J13: =E13-D13 -> 0
A14: 10 | C14: MORIN | D14: 0 | E14: 0 | J14: =E14-D14 -> 0
A15: 11 | C15: MORIN | D15: 0 | E15: 0 | J15: =E15-D15 -> 0
A16: 12 | C16: MORIN | D16: 0 | E16: 0 | J16: =E16-D16 -> 0 | L16: Nb pièce produite (fausse et bonne) | M16: Nombre piéce fausse | N16: nombre piéce bonne | O16: taux qualité | P16: Tcy moyen
A17: 13 | C17: MORIN | D17: 0 | E17: 0 | J17: =E17-D17 -> 0 | L17: =COUNTA(F5:F92) -> 0 | M17: =COUNTIF(F5:F93,"non") -> 0 | N17: =COUNTIF(F5:F92,"oui") -> 0 | O17: =(L17-M17)/L17 -> #DIV/0! | P17: =AVERAGEIF(J$5:J$200,"<>0") -> #DIV/0!
A18: 14 | C18: MORIN | D18: 0 | E18: 0 | J18: =E18-D18 -> 0
A19: 15 | C19: MORIN | D19: 0 | E19: 0 | J19: =E19-D19 -> 0
A20: 16 | C20: MORIN | D20: 0 | E20: 0 | J20: =E20-D20 -> 0
A21: 17 | C21: MORIN | D21: 0 | E21: 0 | J21: =E21-D21 -> 0
A22: 18 | C22: MORIN | D22: 0 | E22: 0 | J22: =E22-D22 -> 0
A23: 19 | C23: MORIN | D23: 0 | E23: 0 | J23: =E23-D23 -> 0
A24: 20 | C24: MORIN | D24: 0 | E24: 0 | J24: =E24-D24 -> 0
A25: 21 | C25: MORIN | D25: 0 | E25: 0 | J25: =E25-D25 -> 0
A26: 22 | C26: MORIN | D26: 0 | E26: 0 | J26: =E26-D26 -> 0
A27: 23 | C27: MORIN | D27: 0 | E27: 0 | J27: =E27-D27 -> 0
A28: 24 | C28: MORIN | D28: 0 | E28: 0 | J28: =E28-D28 -> 0
A29: 25 | C29: MORIN | D29: 0 | E29: 0 | J29: =E29-D29 -> 0
... A81: 77 | C81: MORIN | D81: 0 | E81: 0 | J81: =E81-D81 -> 0

Sheet Equerre ph40
A1: fiche de suivie de production Pièce : Equerre Phase :40
A3: N° | B3: date | C3: opérateur | D3: heure début usinage | E3: heure fin usinage | F3: Conformité | G3: cote 1 | H3: cote 2 | I3: cote 3 | J3: temps de cycle
L4: Nombre pièces conformes
A5: 1 | D5: 0 | E5: 0 | J5: =E5-D5 -> 0 | L5: =COUNTIF(F5:F81,"OUI") -> 0 | M5: /19
A6: 2 | D6: 0 | E6: 0 | J6: =E6-D6 -> 0
A7: 3 | D7: 0 | E7: 0 | J7: =E7-D7 -> 0 | L7: Nombre pièces total
A8: 4 | D8: 0 | E8: 0 | J8: =E8-D8 -> 0 | L8: =COUNTIF(F5:F84,"NON")+L5 -> 0
A9: 5 | D9: 0 | E9: 0 | J9: =E9-D9 -> 0
A10: 6 | D10: 0 | E10: 0 | J10: =E10-D10 -> 0
A11: 7 | D11: 0 | E11: 0 | J11: =E11-D11 -> 0
A12: 8 | D12: 0 | E12: 0 | J12: =E12-D12 -> 0
A13: 9 | D13: 0 | E13: 0 | J13: =E13-D13 -> 0
A14: 10 | D14: 0 | E14: 0 | J14: =E14-D14 -> 0
A15: 11 | D15: 0 | E15: 0 | J15: =E15-D15 -> 0
A16: 12 | D16: 0 | E16: 0 | J16: =E16-D16 -> 0 | L16: Nb pièce produite (fausse et bonne) | M16: Nombre piéce fausse | N16: nombre piéce bonne | O16: taux qualité | P16: Tcy moyen
A17: 13 | D17: 0 | E17: 0 | J17: =E17-D17 -> 0 | L17: =COUNTA(F5:F92) -> 0 | M17: =COUNTIF(F5:F93,"non") -> 0 | N17: =COUNTIF(F5:F92,"oui") -> 0 | O17: =(L17-M17)/L17 -> #DIV/0! | P17: =AVERAGEIF(J$5:J$200,"<>0") -> #DIV/0!
A18: 14 | D18: 0 | E18: 0 | J18: =E18-D18 -> 0
A19: 15 | D19: 0 | E19: 0 | J19: =E19-D19 -> 0
A20: 16 | D20: 0 | E20: 0 | J20: =E20-D20 -> 0
A21: 17 | D21: 0 | E21: 0 | J21: =E21-D21 -> 0
A22: 18 | D22: 0 | E22: 0 | J22: =E22-D22 -> 0
A23: 19 | D23: 0 | E23: 0 | J23: =E23-D23 -> 0
A24: 20 | D24: 0 | E24: 0 | J24: =E24-D24 -> 0
A25: 21 | D25: 0 | E25: 0 | J25: =E25-D25 -> 0
A26: 22 | D26: 0 | E26: 0 | J26: =E26-D26 -> 0
A27: 23 | D27: 0 | E27: 0 | J27: =E27-D27 -> 0
A28: 24 | D28: 0 | E28: 0 | J28: =E28-D28 -> 0
A29: 25 | D29: 0 | E29: 0 | J29: =E29-D29 -> 0
... A81: 77 | D81: 0 | E81: 0 | J81: =E81-D81 -> 0

Sheet Support ph10
A1: fiche de suivie de production Pièce : Support Phase :10
A3: N° | B3: date | C3: opérateur | D3: heure début usinage | E3: heure fin usinage | F3: Conformité | G3: 102+/-0,5 | H3: 102+/-0,5 | I3: 102+/-0,5 | J3: temps de cycle
A5: 1 | B5: 46119 | C5: E.Sanchez | D5: 0.6875 | E5: 0.69513889 | F5: OUI | G5: 101.6 | H5: 101.8 | I5: 101.8 | J5: =E5-D5 -> 0.0076388889
A6: 2 | B6: 46119 | C6: E.Sanchez | D6: 0.70486111 | E6: 0.71041667 | F6: OUI | G6: 102.0 | H6: 101.8 | I6: 101.8 | J6: =E6-D6 -> 0.0055555556
A7: 3 | B7: 46119 | C7: E.Sanchez | D7: 0.71666667 | E7: 0.72638889 | F7: NON | G7: 101.2 | H7: 100.5 | I7: 100.6 | J7: =E7-D7 -> 0.0097222222
A8: 4 | C8: E.Sanchez | D8: 0 | E8: 0 | J8: =E8-D8 -> 0
A9: 5 | C9: E.Sanchez | D9: 0 | E9: 0 | J9: =E9-D9 -> 0
A10: 6 | C10: E.Sanchez | D10: 0 | E10: 0 | J10: =E10-D10 -> 0
A11: 7 | C11: E.Sanchez | D11: 0 | E11: 0 | J11: =E11-D11 -> 0
A12: 8 | C12: E.Sanchez | D12: 0 | E12: 0 | J12: =E12-D12 -> 0
A13: 9 | C13: E.Sanchez | D13: 0 | E13: 0 | J13: =E13-D13 -> 0
A14: 10 | C14: E.Sanchez | D14: 0 | E14: 0 | J14: =E14-D14 -> 0
A15: 11 | C15: E.Sanchez | D15: 0 | E15: 0 | J15: =E15-D15 -> 0
A16: 12 | C16: E.Sanchez | D16: 0 | E16: 0 | J16: =E16-D16 -> 0 | L16: Nb pièce produite (fausse et bonne) | M16: Nombre piéce fausse | N16: nombre piéce bonne | O16: taux qualité | P16: Tcy moyen
A17: 13 | C17: E.Sanchez | D17: 0 | E17: 0 | J17: =E17-D17 -> 0 | L17: =COUNTA(F5:F92) -> 3 | M17: =COUNTIF(F7:F93,"non") -> 1 | N17: =COUNTIF(F7:F92,"oui") -> 0 | O17: =(L17-M17)/L17 -> 0.66666667 | P17: =AVERAGEIF(J$5:J$200,"<>0") -> 0.0076388889
A18: 14 | C18: E.Sanchez | D18: 0 | E18: 0 | J18: =E18-D18 -> 0
A19: 15 | C19: E.Sanchez | D19: 0 | E19: 0 | J19: =E19-D19 -> 0
A20: 16 | C20: E.Sanchez | D20: 0 | E20: 0 | J20: =E20-D20 -> 0
A21: 17 | C21: E.Sanchez | D21: 0 | E21: 0 | J21: =E21-D21 -> 0
A22: 18 | C22: E.Sanchez | D22: 0 | E22: 0 | J22: =E22-D22 -> 0
A23: 19 | C23: E.Sanchez | D23: 0 | E23: 0 | J23: =E23-D23 -> 0
A24: 20 | C24: E.Sanchez | D24: 0 | E24: 0 | J24: =E24-D24 -> 0
A25: 21 | C25: E.Sanchez | D25: 0 | E25: 0 | J25: =E25-D25 -> 0
A26: 22 | C26: E.Sanchez | D26: 0 | E26: 0 | J26: =E26-D26 -> 0
A27: 23 | C27: E.Sanchez | D27: 0 | E27: 0 | J27: =E27-D27 -> 0
A28: 24 | C28: E.Sanchez | D28: 0 | E28: 0 | J28: =E28-D28 -> 0
A29: 25 | C29: E.Sanchez | D29: 0 | E29: 0 | J29: =E29-D29 -> 0
... A69: 65 | C69: E.Sanchez | D69: 0 | E69: 0 | J69: =E69-D69 -> 0
A70: 66 | D70: 0 | E70: 0 | J70: =E70-D70 -> 0
A71: 67 | D71: 0 | E71: 0 | J71: =E71-D71 -> 0
A72: 68 | D72: 0 | E72: 0 | J72: =E72-D72 -> 0
A73: 69 | D73: 0 | E73: 0 | J73: =E73-D73 -> 0
A74: 70 | D74: 0 | E74: 0 | J74: =E74-D74 -> 0
A75: 71 | D75: 0 | E75: 0 | J75: =E75-D75 -> 0
A76: 72 | D76: 0 | E76: 0 | J76: =E76-D76 -> 0
A77: 73 | D77: 0 | E77: 0 | J77: =E77-D77 -> 0
A78: 74 | D78: 0 | E78: 0 | J78: =E78-D78 -> 0
A79: 75 | D79: 0 | E79: 0 | J79: =E79-D79 -> 0
A80: 76 | D80: 0 | E80: 0 | J80: =E80-D80 -> 0
A81: 77 | D81: 0 | E81: 0 | J81: =E81-D81 -> 0

Sheet Support ph15
A1: fiche de suivie de production Pièce : Support Phase :15
A3: N° | B3: date | C3: opérateur | D3: heure début usinage | E3: heure fin usinage | F3: 100 ± 0,5 | G3: Conformité | H3: temps de cycle
A5: 1 | B5: 46119 | C5: Sébastien | D5: 0.69444444 | E5: 0.69930556 | F5: 99.82 | G5: OUI | H5: =E5-D5 -> 0.0048611111
A6: 2 | B6: 46119 | C6: Sébastien | D6: 0.7 | E6: 0.70555556 | F6: 99.62 | G6: OUI | H6: =E6-D6 -> 0.0055555556
A7: 3 | B7: 46119 | C7: Sébastien | D7: 0.70555556 | E7: 0.71041667 | F7: 99.7 | G7: OUI | H7: =E7-D7 -> 0.0048611111
A8: 4 | B8: 46119 | C8: Sébastien | D8: 0.71111111 | E8: 0.71597222 | F8: 99.88 | G8: OUI | H8: =E8-D8 -> 0.0048611111
A9: 5 | B9: 46119 | C9: Sébastien | D9: 0.71666667 | E9: 0.72222222 | F9: 99.82 | G9: OUI | H9: =E9-D9 -> 0.0055555556
A10: 6 | B10: 46119 | C10: Sébastien | D10: 0.72222222 | E10: 0.72708333 | F10: 99.9 | G10: OUI | H10: =E10-D10 -> 0.0048611111
A11: 7 | B11: 46119 | C11: Sébastien | D11: 0.72777778 | E11: 0.73263889 | F11: 99.9 | G11: OUI | H11: =E11-D11 -> 0.0048611111
A12: 8 | C12: Sébastien | D12: 0 | E12: 0 | H12: =E12-D12 -> 0
A13: 9 | C13: Sébastien | D13: 0 | E13: 0 | H13: =E13-D13 -> 0
A14: 10 | C14: Sébastien | D14: 0 | E14: 0 | H14: =E14-D14 -> 0
A15: 11 | C15: Sébastien | D15: 0 | E15: 0 | H15: =E15-D15 -> 0
A16: 12 | C16: Sébastien | D16: 0 | E16: 0 | H16: =E16-D16 -> 0 | J16: Nb pièce produite (fausse et bonne) | K16: Nombre piéce fausse | L16: nombre piéce bonne | M16: taux qualité | N16: Tcy moyen
A17: 13 | C17: Sébastien | D17: 0 | E17: 0 | H17: =E17-D17 -> 0 | J17: =COUNTA(G5:G92) -> 7 | K17: =COUNTIF(G5:G93,"non") -> 0 | L17: =COUNTIF(G5:G92,"oui") -> 7 | M17: =(J17-K17)/J17 -> 1 | N17: =AVERAGEIF(H$5:H$200,"<>0") -> 0.0050595238
A18: 14 | C18: Sébastien | D18: 0 | E18: 0 | H18: =E18-D18 -> 0
A19: 15 | C19: Sébastien | D19: 0 | E19: 0 | H19: =E19-D19 -> 0
A20: 16 | C20: Sébastien | D20: 0 | E20: 0 | H20: =E20-D20 -> 0
A21: 17 | C21: Sébastien | D21: 0 | E21: 0 | H21: =E21-D21 -> 0
A22: 18 | C22: Sébastien | D22: 0 | E22: 0 | H22: =E22-D22 -> 0
A23: 19 | C23: Sébastien | D23: 0 | E23: 0 | H23: =E23-D23 -> 0
A24: 20 | C24: Sébastien | D24: 0 | E24: 0 | H24: =E24-D24 -> 0
A25: 21 | C25: Sébastien | D25: 0 | E25: 0 | H25: =E25-D25 -> 0
A26: 22 | C26: Sébastien | D26: 0 | E26: 0 | H26: =E26-D26 -> 0
A27: 23 | C27: Sébastien | D27: 0 | E27: 0 | H27: =E27-D27 -> 0
A28: 24 | C28: Sébastien | D28: 0 | E28: 0 | H28: =E28-D28 -> 0
A29: 25 | C29: Sébastien | D29: 0 | E29: 0 | H29: =E29-D29 -> 0
... A81: 77 | C81: Sébastien | D81: 0 | E81: 0 | H81: =E81-D81 -> 0

Sheet Support ph20
A1: fiche de suivie de production Pièce : Support Phase :20
A3: N° | B3: date | C3: opérateur | D3: heure début usinage | E3: heure fin usinage | F3: Conformité | G3: Chenfrein1 | H3: Chenfrein2 | I3: Chenfrein3 | J3: Chenfrein4 | K3: temps de cycle
A5: 1 | B5: 46119 | C5: NOCHE | D5: 0.67708333 | E5: 0.6875 | F5: OUI | K5: =E5-D5 -> 0.010416667
A6: 2 | B6: 46119 | C6: NOCHE | D6: 0.6875 | E6: 0.69791667 | F6: OUI | K6: =E6-D6 -> 0.010416667 | M6: Nb pièce produite (fausse et bonne) | N6: Nombre piéce fausse | O6: nombre piéce bonne | P6: taux qualité | Q6: Tcy moyen
A7: 3 | B7: 46119 | C7: NOCHE | D7: 0.69791667 | E7: 0.70833333 | F7: OUI | K7: =E7-D7 -> 0.010416667 | M7: =COUNTA(F5:F92) -> 4 | N7: =COUNTIF(F7:F93,"non") -> 0 | O7: =COUNTIF(F7:F93,"oui") -> 2 | P7: =(M7-N7)/M7 -> 1 | Q7: =AVERAGEIF(K$5:K$200,"<>0") -> 0.010416667
A8: 4 | B8: 46119 | C8: NOCHE | D8: 0.70833333 | E8: 0.71875 | F8: OUI | K8: =E8-D8 -> 0.010416667
A9: 5 | C9: NOCHE | D9: 0 | E9: 0 | K9: =E9-D9 -> 0
A10: 6 | C10: NOCHE | D10: 0 | E10: 0 | K10: =E10-D10 -> 0
A11: 7 | C11: NOCHE | D11: 0 | E11: 0 | K11: =E11-D11 -> 0
A12: 8 | C12: NOCHE | D12: 0 | E12: 0 | K12: =E12-D12 -> 0
A13: 9 | C13: NOCHE | D13: 0 | E13: 0 | K13: =E13-D13 -> 0
A14: 10 | C14: NOCHE | D14: 0 | E14: 0 | K14: =E14-D14 -> 0
A15: 11 | C15: NOCHE | D15: 0 | E15: 0 | K15: =E15-D15 -> 0
A16: 12 | C16: NOCHE | D16: 0 | E16: 0 | K16: =E16-D16 -> 0
A17: 13 | C17: NOCHE | D17: 0 | E17: 0 | K17: =E17-D17 -> 0
A18: 14 | C18: NOCHE | D18: 0 | E18: 0 | K18: =E18-D18 -> 0
A19: 15 | C19: NOCHE | D19: 0 | E19: 0 | K19: =E19-D19 -> 0
A20: 16 | C20: NOCHE | D20: 0 | E20: 0 | K20: =E20-D20 -> 0
... A29: 25 | C29: NOCHE | D29: 0 | E29: 0 | K29: =E29-D29 -> 0
A30: 26 | D30: 0 | E30: 0 | K30: =E30-D30 -> 0
A31: 27 | D31: 0 | E31: 0 | K31: =E31-D31 -> 0
A32: 28 | D32: 0 | E32: 0 | K32: =E32-D32 -> 0
A33: 29 | D33: 0 | E33: 0 | K33: =E33-D33 -> 0
A34: 30 | D34: 0 | E34: 0 | K34: =E34-D34 -> 0
A35: 31 | D35: 0 | E35: 0 | K35: =E35-D35 -> 0
A36: 32 | D36: 0 | E36: 0 | K36: =E36-D36 -> 0
A37: 33 | D37: 0 | E37: 0 | K37: =E37-D37 -> 0
A38: 34 | D38: 0 | E38: 0 | K38: =E38-D38 -> 0
A39: 35 | D39: 0 | E39: 0 | K39: =E39-D39 -> 0
A40: 36 | D40: 0 | E40: 0 | K40: =E40-D40 -> 0
A41: 37 | D41: 0 | E41: 0 | K41: =E41-D41 -> 0
... A81: 77 | D81: 0 | E81: 0 | K81: =E81-D81 -> 0

Sheet Support ph30
A1: fiche de suivie de production Pièce : Support Phase :30
A3: N° | B3: date | C3: opérateur | D3: heure début usinage | E3: heure fin usinage | F3: Conformité | G3: cote 1 | H3: cote 2 | I3: cote 3 | J3: temps de cycle
A5: 1 | D5: 0 | E5: 0 | J5: =E5-D5 -> 0
A6: 2 | D6: 0 | E6: 0 | J6: =E6-D6 -> 0
A7: 3 | D7: 0 | E7: 0 | J7: =E7-D7 -> 0
A8: 4 | D8: 0 | E8: 0 | J8: =E8-D8 -> 0
A9: 5 | D9: 0 | E9: 0 | J9: =E9-D9 -> 0
A10: 6 | D10: 0 | E10: 0 | J10: =E10-D10 -> 0
A11: 7 | D11: 0 | E11: 0 | J11: =E11-D11 -> 0
A12: 8 | D12: 0 | E12: 0 | J12: =E12-D12 -> 0
A13: 9 | D13: 0 | E13: 0 | J13: =E13-D13 -> 0
A14: 10 | D14: 0 | E14: 0 | J14: =E14-D14 -> 0
A15: 11 | D15: 0 | E15: 0 | J15: =E15-D15 -> 0 | L15: Nb pièce produite (fausse et bonne) | M15: Nombre piéce fausse | N15: nombre piéce bonne | O15: taux qualité | P15: Tcy moyen
A16: 12 | D16: 0 | E16: 0 | J16: =E16-D16 -> 0 | L16: =COUNTA(F5:F92) -> 0 | M16: =COUNTIF(F5:F93,"non") -> 0 | N16: =COUNTIF(F5:F92,"oui") -> 0 | O16: =(L16-M16)/L16 -> #DIV/0! | P16: =AVERAGEIF(J$5:J$200,"<>0") -> #DIV/0!
A17: 13 | D17: 0 | E17: 0 | J17: =E17-D17 -> 0
A18: 14 | D18: 0 | E18: 0 | J18: =E18-D18 -> 0
A19: 15 | D19: 0 | E19: 0 | J19: =E19-D19 -> 0
A20: 16 | D20: 0 | E20: 0 | J20: =E20-D20 -> 0
A21: 17 | D21: 0 | E21: 0 | J21: =E21-D21 -> 0
A22: 18 | D22: 0 | E22: 0 | J22: =E22-D22 -> 0
A23: 19 | D23: 0 | E23: 0 | J23: =E23-D23 -> 0
A24: 20 | D24: 0 | E24: 0 | J24: =E24-D24 -> 0
A25: 21 | D25: 0 | E25: 0 | J25: =E25-D25 -> 0
A26: 22 | D26: 0 | E26: 0 | J26: =E26-D26 -> 0
A27: 23 | D27: 0 | E27: 0 | J27: =E27-D27 -> 0
A28: 24 | D28: 0 | E28: 0 | J28: =E28-D28 -> 0
... A81: 77 | D81: 0 | E81: 0 | J81: =E81-D81 -> 0

Sheet Support ph40
A1: fiche de suivie de production Pièce : Support Phase :40
A3: N° | B3: date | C3: opérateur | D3: heure début usinage | E3: heure fin usinage | F3: Conformité | G3: cote 1 | H3: cote 2 | I3: cote 3 | J3: temps de cycle
A5: 1 | C5: MORIN | D5: 0 | E5: 0 | J5: =E5-D5 -> 0
A6: 2 | C6: MORIN | D6: 0 | E6: 0 | J6: =E6-D6 -> 0
A7: 3 | C7: MORIN | D7: 0 | E7: 0 | J7: =E7-D7 -> 0
A8: 4 | C8: MORIN | D8: 0 | E8: 0 | J8: =E8-D8 -> 0
A9: 5 | C9: MORIN | D9: 0 | E9: 0 | J9: =E9-D9 -> 0
A10: 6 | C10: MORIN | D10: 0 | E10: 0 | J10: =E10-D10 -> 0
A11: 7 | C11: MORIN | D11: 0 | E11: 0 | J11: =E11-D11 -> 0
A12: 8 | C12: MORIN | D12: 0 | E12: 0 | J12: =E12-D12 -> 0
A13: 9 | C13: MORIN | D13: 0 | E13: 0 | J13: =E13-D13 -> 0
A14: 10 | C14: MORIN | D14: 0 | E14: 0 | J14: =E14-D14 -> 0
A15: 11 | C15: MORIN | D15: 0 | E15: 0 | J15: =E15-D15 -> 0
A16: 12 | C16: MORIN | D16: 0 | E16: 0 | J16: =E16-D16 -> 0 | L16: Nb pièce produite (fausse et bonne) | M16: Nombre piéce fausse | N16: nombre piéce bonne | O16: taux qualité | P16: Tcy moyen
A17: 13 | C17: MORIN | D17: 0 | E17: 0 | J17: =E17-D17 -> 0 | L17: =COUNTA(F5:F92) -> 0 | M17: =COUNTIF(F5:F93,"non") -> 0 | N17: =COUNTIF(F5:F92,"oui") -> 0 | O17: =(L17-M17)/L17 -> #DIV/0! | P17: =AVERAGEIF(J$5:J$200,"<>0") -> #DIV/0!
A18: 14 | C18: MORIN | D18: 0 | E18: 0 | J18: =E18-D18 -> 0
A19: 15 | C19: MORIN | D19: 0 | E19: 0 | J19: =E19-D19 -> 0
A20: 16 | C20: MORIN | D20: 0 | E20: 0 | J20: =E20-D20 -> 0
A21: 17 | C21: MORIN | D21: 0 | E21: 0 | J21: =E21-D21 -> 0
A22: 18 | C22: MORIN | D22: 0 | E22: 0 | J22: =E22-D22 -> 0
A23: 19 | C23: MORIN | D23: 0 | E23: 0 | J23: =E23-D23 -> 0
A24: 20 | C24: MORIN | D24: 0 | E24: 0 | J24: =E24-D24 -> 0
A25: 21 | C25: MORIN | D25: 0 | E25: 0 | J25: =E25-D25 -> 0
A26: 22 | C26: MORIN | D26: 0 | E26: 0 | J26: =E26-D26 -> 0
A27: 23 | C27: MORIN | D27: 0 | E27: 0 | J27: =E27-D27 -> 0
A28: 24 | C28: MORIN | D28: 0 | E28: 0 | J28: =E28-D28 -> 0
A29: 25 | C29: MORIN | D29: 0 | E29: 0 | J29: =E29-D29 -> 0
... A81: 77 | C81: MORIN | D81: 0 | E81: 0 | J81: =E81-D81 -> 0

Sheet Support ph50
A1: fiche de suivie de production Pièce : Support Phase :50
A3: N° | B3: date | C3: opérateur | D3: heure début usinage | E3: heure fin usinage | F3: Conformité | G3: cote 1 | H3: cote 2 | I3: cote 3 | J3: temps de cycle
A5: 1 | D5: 0 | E5: 0 | J5: =E5-D5 -> 0
A6: 2 | D6: 0 | E6: 0 | J6: =E6-D6 -> 0
A7: 3 | D7: 0 | E7: 0 | J7: =E7-D7 -> 0
A8: 4 | D8: 0 | E8: 0 | J8: =E8-D8 -> 0
A9: 5 | D9: 0 | E9: 0 | J9: =E9-D9 -> 0
A10: 6 | D10: 0 | E10: 0 | J10: =E10-D10 -> 0
A11: 7 | D11: 0 | E11: 0 | J11: =E11-D11 -> 0
A12: 8 | D12: 0 | E12: 0 | J12: =E12-D12 -> 0
A13: 9 | D13: 0 | E13: 0 | J13: =E13-D13 -> 0
A14: 10 | D14: 0 | E14: 0 | J14: =E14-D14 -> 0
A15: 11 | D15: 0 | E15: 0 | J15: =E15-D15 -> 0
A16: 12 | D16: 0 | E16: 0 | J16: =E16-D16 -> 0 | L16: Nb pièce produite (fausse et bonne) | M16: Nombre piéce fausse | N16: nombre piéce bonne | O16: taux qualité | P16: Tcy moyen
A17: 13 | D17: 0 | E17: 0 | J17: =E17-D17 -> 0 | L17: =COUNTA(F5:F92) -> 0 | M17: =COUNTIF(F5:F93,"non") -> 0 | N17: =COUNTIF(F5:F92,"oui") -> 0 | O17: =(L17-M17)/L17 -> #DIV/0! | P17: =AVERAGEIF(J$5:J$200,"<>0") -> #DIV/0!
A18: 14 | D18: 0 | E18: 0 | J18: =E18-D18 -> 0
A19: 15 | D19: 0 | E19: 0 | J19: =E19-D19 -> 0
A20: 16 | D20: 0 | E20: 0 | J20: =E20-D20 -> 0
A21: 17 | D21: 0 | E21: 0 | J21: =E21-D21 -> 0
A22: 18 | D22: 0 | E22: 0 | J22: =E22-D22 -> 0
A23: 19 | D23: 0 | E23: 0 | J23: =E23-D23 -> 0
A24: 20 | D24: 0 | E24: 0 | J24: =E24-D24 -> 0
A25: 21 | D25: 0 | E25: 0 | J25: =E25-D25 -> 0
A26: 22 | D26: 0 | E26: 0 | J26: =E26-D26 -> 0
A27: 23 | D27: 0 | E27: 0 | J27: =E27-D27 -> 0
A28: 24 | D28: 0 | E28: 0 | J28: =E28-D28 -> 0
A29: 25 | D29: 0 | E29: 0 | J29: =E29-D29 -> 0
... A81: 77 | D81: 0 | E81: 0 | J81: =E81-D81 -> 0

Sheet Support ph60
A1: fiche de suivie de production Pièce : Support Phase 60
A3: N° | B3: date | C3: opérateur | D3: heure début usinage | E3: heure fin usinage | F3: Conformité | G3: cote 1 | H3: cote 2 | I3: cote 3 | J3: temps de cycle
L4: Nombre pièces conformes
A5: 1 | D5: 0 | E5: 0 | J5: =$E5-$D5 -> 0 | L5: =COUNTIF(F5:F81,"OUI") -> 0 | M5: /19
A6: 2 | D6: 0 | E6: 0 | J6: =$E6-$D6 -> 0
A7: 3 | D7: 0 | E7: 0 | J7: =$E7-$D7 -> 0 | L7: Nombre pièces total
A8: 4 | D8: 0 | E8: 0 | J8: =$E8-$D8 -> 0 | L8: =COUNTIF(F5:F84,"NON")+L5 -> 0
A9: 5 | D9: 0 | E9: 0 | J9: =$E9-$D9 -> 0
A10: 6 | D10: 0 | E10: 0 | J10: =$E10-$D10 -> 0
A11: 7 | D11: 0 | E11: 0 | J11: =$E11-$D11 -> 0
A12: 8 | D12: 0 | E12: 0 | J12: =$E12-$D12 -> 0
A13: 9 | D13: 0 | E13: 0 | J13: =$E13-$D13 -> 0
A14: 10 | D14: 0 | E14: 0 | J14: =$E14-$D14 -> 0
A15: 11 | D15: 0 | E15: 0 | J15: =$E15-$D15 -> 0
A16: 12 | D16: 0 | E16: 0 | J16: =$E16-$D16 -> 0 | L16: Nb pièce produite (fausse et bonne) | M16: Nombre piéce fausse | N16: nombre piéce bonne | O16: taux qualité | P16: Tcy moyen
A17: 13 | D17: 0 | E17: 0 | J17: =$E17-$D17 -> 0 | L17: =COUNTA(F5:F92) -> 0 | M17: =COUNTIF(F5:F93,"non") -> 0 | N17: =COUNTIF(F5:F92,"oui") -> 0 | O17: =(L17-M17)/L17 -> #DIV/0! | P17: =AVERAGEIF(J$5:J$200,"<>0") -> #DIV/0!
A18: 14 | D18: 0 | E18: 0 | J18: =$E18-$D18 -> 0
A19: 15 | D19: 0 | E19: 0 | J19: =$E19-$D19 -> 0
A20: 16 | D20: 0 | E20: 0 | J20: =$E20-$D20 -> 0
A21: 17 | D21: 0 | E21: 0 | J21: =$E21-$D21 -> 0
A22: 18 | D22: 0 | E22: 0 | J22: =$E22-$D22 -> 0
A23: 19 | D23: 0 | E23: 0 | J23: =$E23-$D23 -> 0
A24: 20 | D24: 0 | E24: 0 | J24: =$E24-$D24 -> 0
A25: 21 | D25: 0 | E25: 0 | J25: =$E25-$D25 -> 0
A26: 22 | D26: 0 | E26: 0 | J26: =$E26-$D26 -> 0
A27: 23 | D27: 0 | E27: 0 | J27: =$E27-$D27 -> 0
A28: 24 | D28: 0 | E28: 0 | J28: =$E28-$D28 -> 0
A29: 25 | D29: 0 | E29: 0 | J29: =$E29-$D29 -> 0
... A81: 77 | D81: 0 | E81: 0 | J81: =$E81-$D81 -> 0

Sheet Palier ph10
A1: fiche de suivie de production Pièce : Palier Phase :10
A3: N° | B3: date | C3: opérateur | D3: heure début usinage | E3: heure fin usinage | F3: Conformité | G3: Ø10 | H3: 36,1±0,03 | I3: Ø8f7 | J3: Ø 9,6±0,2 | K3: temps de cycle | L3: Commentaires
A5: 1 | B5: 46119 | D5: 0.67152778 | E5: 0.67361111 | F5: NON | G5: 9.91 | H5: 36.1 | I5: 7.944 | J5: 9.6 | K5: =E5-D5 -> 0.0020833333 | L5: Mise en place du premier brut pour faire chauffer la broche | M5: Nombre pièces conformes
A6: 2 | B6: 46119 | D6: 0.67708333 | E6: 0.67916667 | F6: NON | G6: 9.9 | H6: 36.11 | I6: 7.952 | J6: 9.6 | K6: =E6-D6 -> 0.0020833333 | L6: Correction de la jauge outil pour les pièces suivante | M6: =COUNTIF(F5:F81,"OUI") -> 0 | N6: /38
A7: 3 | B7: 46119 | D7: 0.69791667 | E7: 0.70833333 | F7: NON | G7: 9.898 | H7: 36.1 | I7: 7.955 | J7: 9.54 | K7: =E7-D7 -> 0.010416667
A8: 4 | B8: 46119 | D8: 0.70625 | E8: 0.71527778 | F8: NON | G8: 0 | H8: 0 | I8: 0 | J8: 0 | K8: =E8-D8 -> 0.0090277778 | L8: Erreur de modification de jauge outil | M8: Nombre pièces total
A9: 5 | B9: 46119 | D9: 0.71666667 | E9: 0.72152778 | F9: NON | G9: 9.886 | H9: 36.2 | I9: 7.993 | J9: 9.57 | K9: =E9-D9 -> 0.0048611111 | M9: =COUNTIF(F5:F84,"NON")+M6 -> 7
A10: 6 | B10: 46119 | D10: 0.71875 | E10: 0.725 | F10: NON | G10: 9.888 | H10: 36.21 | I10: 7.932 | J10: 9.56 | K10: =E10-D10 -> 0.00625 | L10: Nouveaux brut
A11: 7 | B11: 46119 | D11: 0.72916667 | E11: 0.73333333 | F11: NON | G11: 9.895 | H11: 36.175 | I11: 7.936 | J11: 9.575 | K11: =E11-D11 -> 0.0041666667
A12: 8 | D12: 0 | E12: 0 | K12: =E12-D12 -> 0
A13: 9 | D13: 0 | E13: 0 | K13: =E13-D13 -> 0
A14: 10 | D14: 0 | E14: 0 | K14: =E14-D14 -> 0
A15: 11 | D15: 0 | E15: 0 | K15: =E15-D15 -> 0
A16: 12 | D16: 0 | E16: 0 | K16: =E16-D16 -> 0 | M16: Nb pièce produite (fausse et bonne) | N16: Nombre piéce fausse | O16: nombre piéce bonne | P16: taux qualité | Q16: Tcy moyen
A17: 13 | D17: 0 | E17: 0 | K17: =E17-D17 -> 0 | M17: =COUNTA(F5:F92) -> 7 | N17: =COUNTIF(F5:F93,"non") -> 7 | O17: =COUNTIF(F5:F92,"oui") -> 0 | P17: =(M17-N17)/M17 -> 0 | Q17: =AVERAGEIF(K$5:K$200,"<>0") -> 0.0055555556
A18: 14 | D18: 0 | E18: 0 | K18: =E18-D18 -> 0
A19: 15 | D19: 0 | E19: 0 | K19: =E19-D19 -> 0
A20: 16 | D20: 0 | E20: 0 | K20: =E20-D20 -> 0
A21: 17 | D21: 0 | E21: 0 | K21: =E21-D21 -> 0
A22: 18 | D22: 0 | E22: 0 | K22: =E22-D22 -> 0
A23: 19 | D23: 0 | E23: 0 | K23: =E23-D23 -> 0
A24: 20 | D24: 0 | E24: 0 | K24: =E24-D24 -> 0
A25: 21 | D25: 0 | E25: 0 | K25: =E25-D25 -> 0
A26: 22 | D26: 0 | E26: 0 | K26: =E26-D26 -> 0
A27: 23 | D27: 0 | E27: 0 | K27: =E27-D27 -> 0
A28: 24 | D28: 0 | E28: 0 | K28: =E28-D28 -> 0
A29: 25 | D29: 0 | E29: 0 | K29: =E29-D29 -> 0
... A81: 77 | D81: 0 | E81: 0 | K81: =E81-D81 -> 0
A82: 78 | D82: 0 | E82: 0 | K82: =$E82-$D82 -> 0
A83: 79 | D83: 0 | E83: 0 | K83: =$E83-$D83 -> 0
A84: 80 | D84: 0 | E84: 0 | K84: =$E84-$D84 -> 0
A85: 81 | D85: 0 | E85: 0 | K85: =$E85-$D85 -> 0
A86: 82 | D86: 0 | E86: 0 | K86: =$E86-$D86 -> 0
A87: 83 | D87: 0 | E87: 0 | K87: =$E87-$D87 -> 0
A88: 84 | D88: 0 | E88: 0 | K88: =$E88-$D88 -> 0
A89: 85 | D89: 0 | E89: 0 | K89: =$E89-$D89 -> 0
A90: 86 | D90: 0 | E90: 0 | K90: =$E90-$D90 -> 0
A91: 87 | D91: 0 | E91: 0 | K91: =$E91-$D91 -> 0
A92: 88 | D92: 0 | E92: 0 | K92: =$E92-$D92 -> 0
A93: 89 | D93: 0 | E93: 0 | K93: =$E93-$D93 -> 0
...

Sheet Palier ph20
A1: fiche de suivie de production Pièce : Palier Phase :20
A3: N° | B3: date | C3: opérateur | D3: heure début usinage | E3: heure fin usinage | F3: Conformité | G3: cote 1 | H3: cote 2 | I3: cote 3 | J3: temps de cycle
L4: Nombre pièces conformes
A5: 1 | D5: 0 | E5: 0 | J5: =E5-D5 -> 0 | L5: =COUNTIF(F5:F81,"OUI") -> 0 | M5: /19
A6: 2 | D6: 0 | E6: 0 | J6: =E6-D6 -> 0
A7: 3 | D7: 0 | E7: 0 | J7: =E7-D7 -> 0 | L7: Nombre pièces total
A8: 4 | D8: 0 | E8: 0 | J8: =E8-D8 -> 0 | L8: =COUNTIF(F5:F84,"NON")+L5 -> 0
A9: 5 | D9: 0 | E9: 0 | J9: =E9-D9 -> 0
A10: 6 | D10: 0 | E10: 0 | J10: =E10-D10 -> 0
A11: 7 | D11: 0 | E11: 0 | J11: =E11-D11 -> 0
A12: 8 | D12: 0 | E12: 0 | J12: =E12-D12 -> 0
A13: 9 | D13: 0 | E13: 0 | J13: =E13-D13 -> 0
A14: 10 | D14: 0 | E14: 0 | J14: =E14-D14 -> 0
A15: 11 | D15: 0 | E15: 0 | J15: =E15-D15 -> 0
A16: 12 | D16: 0 | E16: 0 | J16: =E16-D16 -> 0 | L16: Nb pièce produite (fausse et bonne) | M16: Nombre piéce fausse | N16: nombre piéce bonne | O16: taux qualité | P16: Tcy moyen
A17: 13 | D17: 0 | E17: 0 | J17: =E17-D17 -> 0 | L17: =COUNTA(F5:F92) -> 0 | M17: =COUNTIF(F5:F93,"non") -> 0 | N17: =COUNTIF(F5:F92,"oui") -> 0 | O17: =(L17-M17)/L17 -> #DIV/0! | P17: =AVERAGEIF(J$5:J$200,"<>0") -> #DIV/0!
A18: 14 | D18: 0 | E18: 0 | J18: =E18-D18 -> 0
A19: 15 | D19: 0 | E19: 0 | J19: =E19-D19 -> 0
A20: 16 | D20: 0 | E20: 0 | J20: =E20-D20 -> 0
A21: 17 | D21: 0 | E21: 0 | J21: =E21-D21 -> 0
A22: 18 | D22: 0 | E22: 0 | J22: =E22-D22 -> 0
A23: 19 | D23: 0 | E23: 0 | J23: =E23-D23 -> 0
A24: 20 | D24: 0 | E24: 0 | J24: =E24-D24 -> 0
A25: 21 | D25: 0 | E25: 0 | J25: =E25-D25 -> 0
A26: 22 | D26: 0 | E26: 0 | J26: =E26-D26 -> 0
A27: 23 | D27: 0 | E27: 0 | J27: =E27-D27 -> 0
A28: 24 | D28: 0 | E28: 0 | J28: =E28-D28 -> 0
A29: 25 | D29: 0 | E29: 0 | J29: =E29-D29 -> 0
... A81: 77 | D81: 0 | E81: 0 | J81: =E81-D81 -> 0

Sheet Cylindre ph10
A1: fiche de suivie de production Pièce : Cylindre Phase :10
A3: N° | B3: date | C3: opérateur | D3: heure début usinage | E3: heure fin usinage | F3: Conformité | G3: cote 1 | H3: cote 2 | I3: cote 3 | J3: temps de cycle
A5: 1 | D5: 0 | E5: 0 | J5: =E5-D5 -> 0
A6: 2 | D6: 0 | E6: 0 | J6: =E6-D6 -> 0
A7: 3 | D7: 0 | E7: 0 | J7: =E7-D7 -> 0
A8: 4 | D8: 0 | E8: 0 | J8: =E8-D8 -> 0
A9: 5 | D9: 0 | E9: 0 | J9: =E9-D9 -> 0
A10: 6 | D10: 0 | E10: 0 | J10: =E10-D10 -> 0
A11: 7 | D11: 0 | E11: 0 | J11: =E11-D11 -> 0
A12: 8 | D12: 0 | E12: 0 | J12: =E12-D12 -> 0
A13: 9 | D13: 0 | E13: 0 | J13: =E13-D13 -> 0
A14: 10 | D14: 0 | E14: 0 | J14: =E14-D14 -> 0
A15: 11 | D15: 0 | E15: 0 | J15: =E15-D15 -> 0
A16: 12 | D16: 0 | E16: 0 | J16: =E16-D16 -> 0 | L16: Nb pièce produite (fausse et bonne) | M16: Nombre piéce fausse | N16: nombre piéce bonne | O16: taux qualité | P16: Tcy moyen
A17: 13 | D17: 0 | E17: 0 | J17: =E17-D17 -> 0 | L17: =COUNTA(F5:F92) -> 0 | M17: =COUNTIF(F5:F93,"non") -> 0 | N17: =COUNTIF(F5:F92,"oui") -> 0 | O17: =(L17-M17)/L17 -> #DIV/0! | P17: =AVERAGEIF(J$5:J$200,"<>0") -> #DIV/0!
A18: 14 | D18: 0 | E18: 0 | J18: =E18-D18 -> 0
A19: 15 | D19: 0 | E19: 0 | J19: =E19-D19 -> 0
A20: 16 | D20: 0 | E20: 0 | J20: =E20-D20 -> 0
A21: 17 | D21: 0 | E21: 0 | J21: =E21-D21 -> 0
A22: 18 | D22: 0 | E22: 0 | J22: =E22-D22 -> 0
A23: 19 | D23: 0 | E23: 0 | J23: =E23-D23 -> 0
A24: 20 | D24: 0 | E24: 0 | J24: =E24-D24 -> 0
A25: 21 | D25: 0 | E25: 0 | J25: =E25-D25 -> 0
A26: 22 | D26: 0 | E26: 0 | J26: =E26-D26 -> 0
A27: 23 | D27: 0 | E27: 0 | J27: =E27-D27 -> 0
A28: 24 | D28: 0 | E28: 0 | J28: =E28-D28 -> 0
A29: 25 | D29: 0 | E29: 0 | J29: =E29-D29 -> 0
... A81: 77 | D81: 0 | E81: 0 | J81: =E81-D81 -> 0

Sheet Cylindre ph20
A1: fiche de suivie de production Pièce : Support Phase :10
A3: N° | B3: date | C3: opérateur | D3: heure début usinage | E3: heure fin usinage | F3: Conformité | G3: cote 1 | H3: cote 2 | I3: cote 3 | J3: temps de cycle
A5: 1 | D5: 0 | E5: 0 | J5: =E5-D5 -> 0
A6: 2 | D6: 0 | E6: 0 | J6: =E6-D6 -> 0
A7: 3 | D7: 0 | E7: 0 | J7: =E7-D7 -> 0
A8: 4 | D8: 0 | E8: 0 | J8: =E8-D8 -> 0
A9: 5 | D9: 0 | E9: 0 | J9: =E9-D9 -> 0
A10: 6 | D10: 0 | E10: 0 | J10: =E10-D10 -> 0
A11: 7 | D11: 0 | E11: 0 | J11: =E11-D11 -> 0
A12: 8 | D12: 0 | E12: 0 | J12: =E12-D12 -> 0
A13: 9 | D13: 0 | E13: 0 | J13: =E13-D13 -> 0
A14: 10 | D14: 0 | E14: 0 | J14: =E14-D14 -> 0
A15: 11 | D15: 0 | E15: 0 | J15: =E15-D15 -> 0
A16: 12 | D16: 0 | E16: 0 | J16: =E16-D16 -> 0 | L16: Nb pièce produite (fausse et bonne) | M16: Nombre piéce fausse | N16: nombre piéce bonne | O16: taux qualité | P16: Tcy moyen
A17: 13 | D17: 0 | E17: 0 | J17: =E17-D17 -> 0 | L17: =COUNTA(F5:F92) -> 0 | M17: =COUNTIF(F5:F93,"non") -> 0 | N17: =COUNTIF(F5:F92,"oui") -> 0 | O17: =(L17-M17)/L17 -> #DIV/0! | P17: =AVERAGEIF(J$5:J$200,"<>0") -> #DIV/0!
A18: 14 | D18: 0 | E18: 0 | J18: =E18-D18 -> 0
A19: 15 | D19: 0 | E19: 0 | J19: =E19-D19 -> 0
A20: 16 | D20: 0 | E20: 0 | J20: =E20-D20 -> 0
A21: 17 | D21: 0 | E21: 0 | J21: =E21-D21 -> 0
A22: 18 | D22: 0 | E22: 0 | J22: =E22-D22 -> 0
A23: 19 | D23: 0 | E23: 0 | J23: =E23-D23 -> 0
A24: 20 | D24: 0 | E24: 0 | J24: =E24-D24 -> 0
A25: 21 | D25: 0 | E25: 0 | J25: =E25-D25 -> 0
A26: 22 | D26: 0 | E26: 0 | J26: =E26-D26 -> 0
A27: 23 | D27: 0 | E27: 0 | J27: =E27-D27 -> 0
A28: 24 | D28: 0 | E28: 0 | J28: =E28-D28 -> 0
A29: 25 | D29: 0 | E29: 0 | J29: =E29-D29 -> 0
... A81: 77 | D81: 0 | E81: 0 | J81: =E81-D81 -> 0
B1000: 45776

Sheet Cylindre ph30
A1: fiche de suivie de production Pièce : Cylindre Phase :30
A3: N° | B3: date | C3: opérateur | D3: heure début usinage | E3: heure fin usinage | F3: Conformité | G3: 13±0,25 | H3: Ø10H7 | I3: 3*Ø8H7 | J3: Ø22 | K3: temps de cycle
A5: 1 | C5: CARDINALE | K5: =E5-D5 -> 0 | M5: Nombre pièces conformes
A6: 2 | C6: CARDINALE | K6: =E6-D6 -> 0 | M6: =COUNTIF(F5:F81,"OUI") -> 0 | N6: /38
A7: 3 | C7: CARDINALE | K7: =E7-D7 -> 0
A8: 4 | C8: CARDINALE | K8: =E8-D8 -> 0 | M8: Nombre pièces total
A9: 5 | C9: CARDINALE | K9: =E9-D9 -> 0 | M9: =COUNTIF(F5:F84,"NON")+M6 -> 0
A10: 6 | C10: CARDINALE | K10: =E10-D10 -> 0
A11: 7 | C11: CARDINALE | K11: =E11-D11 -> 0
A12: 8 | C12: CARDINALE | K12: =E12-D12 -> 0
A13: 9 | C13: CARDINALE | K13: =E13-D13 -> 0
A14: 10 | C14: CARDINALE | K14: =E14-D14 -> 0
A15: 11 | C15: CARDINALE | K15: =E15-D15 -> 0
A16: 12 | C16: CARDINALE | K16: =E16-D16 -> 0 | M16: Nb pièce produite (fausse et bonne) | N16: Nombre piéce fausse | O16: nombre piéce bonne | P16: taux qualité | Q16: Tcy moyen
A17: 13 | C17: CARDINALE | K17: =E17-D17 -> 0 | M17: =COUNTA(F5:F92) -> 0 | N17: =COUNTIF(F5:F93,"non") -> 0 | O17: =COUNTIF(F5:F92,"oui") -> 0 | P17: =(M17-N17)/M17 -> #DIV/0! | Q17: =AVERAGEIF(K$5:K$200,"<>0") -> #DIV/0!
A18: 14 | C18: CARDINALE | K18: =E18-D18 -> 0
A19: 15 | C19: CARDINALE | K19: =E19-D19 -> 0
A20: 16 | C20: CARDINALE | K20: =E20-D20 -> 0
A21: 17 | C21: CARDINALE | K21: =E21-D21 -> 0
A22: 18 | C22: CARDINALE | K22: =E22-D22 -> 0
A23: 19 | C23: CARDINALE | K23: =E23-D23 -> 0
A24: 20 | C24: CARDINALE | K24: =E24-D24 -> 0
A25: 21 | C25: CARDINALE | K25: =E25-D25 -> 0
A26: 22 | C26: CARDINALE | K26: =E26-D26 -> 0
A27: 23 | C27: CARDINALE | K27: =E27-D27 -> 0
A28: 24 | C28: CARDINALE | K28: =E28-D28 -> 0
A29: 25 | C29: CARDINALE | K29: =E29-D29 -> 0
... A81: 77 | C81: CARDINALE | K81: =E81-D81 -> 0

Sheet Volant ph0
A1: fiche de suivie de production Pièce : Volant Phase :0
A3: N° | B3: date | C3: opérateur | D3: heure début usinage | E3: heure fin usinage | F3: Conformité | J3: temps de cycle
A5: 1 | B5: 46119 | C5: E.OUALI - DENISART | D5: 0 | E5: 0 | J5: =E5-D5 -> 0
A6: 2 | C6: E.OUALI - DENISART | D6: 0 | E6: 0 | J6: =E6-D6 -> 0
A7: 3 | C7: E.OUALI - DENISART | D7: 0 | E7: 0 | J7: =E7-D7 -> 0
A8: 4 | C8: E.OUALI - DENISART | D8: 0 | E8: 0 | J8: =E8-D8 -> 0
A9: 5 | C9: E.OUALI - DENISART | D9: 0 | E9: 0 | J9: =E9-D9 -> 0
A10: 6 | C10: E.OUALI - DENISART | D10: 0 | E10: 0 | J10: =E10-D10 -> 0
A11: 7 | C11: E.OUALI - DENISART | D11: 0 | E11: 0 | J11: =E11-D11 -> 0
A12: 8 | C12: E.OUALI - DENISART | D12: 0 | E12: 0 | J12: =E12-D12 -> 0
A13: 9 | C13: E.OUALI - DENISART | D13: 0 | E13: 0 | J13: =E13-D13 -> 0
A14: 10 | C14: E.OUALI - DENISART | D14: 0 | E14: 0 | J14: =E14-D14 -> 0
A15: 11 | C15: E.OUALI - DENISART | D15: 0 | E15: 0 | J15: =E15-D15 -> 0
A16: 12 | C16: E.OUALI - DENISART | D16: 0 | E16: 0 | J16: =E16-D16 -> 0 | L16: Nb pièce produite (fausse et bonne) | M16: Nombre piéce fausse | N16: nombre piéce bonne | O16: taux qualité | P16: Tcy moyen
A17: 13 | C17: E.OUALI - DENISART | D17: 0 | E17: 0 | J17: =E17-D17 -> 0 | L17: =COUNTA(G5:G92) -> 0 | M17: =COUNTIF(G5:G500,"non") -> 0 | N17: =COUNTIF(F5:F92,"oui") -> 0 | O17: =(L17-M17)/L17 -> #DIV/0! | P17: =AVERAGEIF(J$5:J$200,"<>0") -> #DIV/0!
A18: 14 | C18: E.OUALI - DENISART | D18: 0 | E18: 0 | J18: =E18-D18 -> 0
A19: 15 | C19: E.OUALI - DENISART | D19: 0 | E19: 0 | J19: =E19-D19 -> 0 | L19: Nombre de pièces | M19: Masse rajoutée (en kg)
A20: 16 | C20: E.OUALI - DENISART | D20: 0 | E20: 0 | J20: =E20-D20 -> 0
A21: 17 | C21: E.OUALI - DENISART | D21: 0 | E21: 0 | J21: =E21-D21 -> 0
A22: 18 | C22: E.OUALI - DENISART | D22: 0 | E22: 0 | J22: =E22-D22 -> 0
A23: 19 | C23: E.OUALI - DENISART | D23: 0 | E23: 0 | J23: =E23-D23 -> 0
A24: 20 | C24: E.OUALI - DENISART | D24: 0 | E24: 0 | J24: =E24-D24 -> 0
A25: 21 | C25: E.OUALI - DENISART | D25: 0 | E25: 0 | J25: =E25-D25 -> 0
A26: 22 | C26: E.OUALI - DENISART | D26: 0 | E26: 0 | J26: =E26-D26 -> 0
A27: 23 | C27: E.OUALI - DENISART | D27: 0 | E27: 0 | J27: =E27-D27 -> 0
A28: 24 | C28: E.OUALI - DENISART | D28: 0 | E28: 0 | J28: =E28-D28 -> 0
A29: 25 | C29: E.OUALI - DENISART | D29: 0 | E29: 0 | J29: =E29-D29 -> 0
A30: 26 | C30: E.OUALI - DENISART | D30: 0 | E30: 0 | J30: =E30-D30 -> 0
A31: 27 | C31: E.OUALI - DENISART | D31: 0 | E31: 0 | J31: =E31-D31 -> 0
... A33: 29 | C33: E.OUALI - DENISART | D33: 0 | E33: 0 | J33: =E33-D33 -> 0
A34: 30 | D34: 0 | E34: 0 | J34: =E34-D34 -> 0
A35: 31 | D35: 0 | E35: 0 | J35: =E35-D35 -> 0
A36: 32 | D36: 0 | E36: 0 | J36: =E36-D36 -> 0
A37: 33 | D37: 0 | E37: 0 | J37: =E37-D37 -> 0
A38: 34 | D38: 0 | E38: 0 | J38: =E38-D38 -> 0
A39: 35 | D39: 0 | E39: 0 | J39: =E39-D39 -> 0
A40: 36 | D40: 0 | E40: 0 | J40: =E40-D40 -> 0
A41: 37 | D41: 0 | E41: 0 | J41: =E41-D41 -> 0
A42: 38 | D42: 0 | E42: 0 | J42: =E42-D42 -> 0
A43: 39 | D43: 0 | E43: 0 | J43: =E43-D43 -> 0
...

Sheet Volant ph10
A1: fiche de suivie de production Pièce : Volant Phase :10
A3: N° | B3: date | C3: opérateur | D3: heure début usinage | E3: heure fin usinage | F3: Conformité | G3: cote 1 | H3: cote 2 | I3: cote 3 | J3: temps de cycle
A5: 1 | D5: 0 | E5: 0 | J5: =E5-D5 -> 0
A6: 2 | D6: 0 | E6: 0 | J6: =E6-D6 -> 0
A7: 3 | D7: 0 | E7: 0 | J7: =E7-D7 -> 0
A8: 4 | D8: 0 | E8: 0 | J8: =E8-D8 -> 0
A9: 5 | D9: 0 | E9: 0 | J9: =E9-D9 -> 0
A10: 6 | D10: 0 | E10: 0 | J10: =E10-D10 -> 0
A11: 7 | D11: 0 | E11: 0 | J11: =E11-D11 -> 0
A12: 8 | D12: 0 | E12: 0 | J12: =E12-D12 -> 0
A13: 9 | D13: 0 | E13: 0 | J13: =E13-D13 -> 0
A14: 10 | D14: 0 | E14: 0 | J14: =E14-D14 -> 0
A15: 11 | D15: 0 | E15: 0 | J15: =E15-D15 -> 0
A16: 12 | D16: 0 | E16: 0 | J16: =E16-D16 -> 0 | L16: Nb pièce produite (fausse et bonne) | M16: Nombre piéce fausse | N16: nombre piéce bonne | O16: taux qualité | P16: Tcy moyen
A17: 13 | D17: 0 | E17: 0 | J17: =E17-D17 -> 0 | L17: =COUNTA(F5:F92) -> 0 | M17: =COUNTIF(F5:F93,"non") -> 0 | N17: =COUNTIF(F5:F92,"oui") -> 0 | O17: =(L17-M17)/L17 -> #DIV/0! | P17: =AVERAGEIF(J$5:J$200,"<>0") -> #DIV/0!
A18: 14 | D18: 0 | E18: 0 | J18: =E18-D18 -> 0
A19: 15 | D19: 0 | E19: 0 | J19: =E19-D19 -> 0
A20: 16 | D20: 0 | E20: 0 | J20: =E20-D20 -> 0
A21: 17 | D21: 0 | E21: 0 | J21: =E21-D21 -> 0
A22: 18 | D22: 0 | E22: 0 | J22: =E22-D22 -> 0
A23: 19 | D23: 0 | E23: 0 | J23: =E23-D23 -> 0
A24: 20 | D24: 0 | E24: 0 | J24: =E24-D24 -> 0
A25: 21 | D25: 0 | E25: 0 | J25: =E25-D25 -> 0
A26: 22 | D26: 0 | E26: 0 | J26: =E26-D26 -> 0
A27: 23 | D27: 0 | E27: 0 | J27: =E27-D27 -> 0
A28: 24 | D28: 0 | E28: 0 | J28: =E28-D28 -> 0
A29: 25 | D29: 0 | E29: 0 | J29: =E29-D29 -> 0
... A81: 77 | D81: 0 | E81: 0 | J81: =E81-D81 -> 0

Sheet Volant ph20
A1: fiche de suivie de production Pièce : Volant :20
A3: N° | B3: date | C3: opérateur | D3: heure début usinage | E3: heure fin usinage | F3: 84 ± 0,5 | G3: 82 + 0,3 / 0 | H3: 15 + 0,3 / 0 | I3: 5 ± 0,5 | J3: Conformité | K3: temps de cycle
A5: 1 | B5: 46119 | C5: DAUDET | D5: 0.63194444 | E5: 0.68263889 | F5: 84 | G5: 82.1 | H5: 15.15 | I5: 5.2 | J5: OUI | K5: =E5-D5 -> 0.050694444
A6: 2 | C6: DAUDET | D6: 0.71875 | E6: 0.73611111 | F6: 84.15 | G6: 81.7 | J6: NON | K6: =E6-D6 -> 0.017361111
A7: 3 | C7: DAUDET | D7: 0 | E7: 0 | K7: =E7-D7 -> 0
A8: 4 | C8: DAUDET | D8: 0 | E8: 0 | K8: =E8-D8 -> 0
A9: 5 | C9: DAUDET | D9: 0 | E9: 0 | K9: =E9-D9 -> 0
A10: 6 | C10: DAUDET | D10: 0 | E10: 0 | K10: =E10-D10 -> 0
A11: 7 | C11: DAUDET | D11: 0 | E11: 0 | K11: =E11-D11 -> 0
A12: 8 | C12: DAUDET | D12: 0 | E12: 0 | K12: =E12-D12 -> 0
A13: 9 | C13: DAUDET | D13: 0 | E13: 0 | K13: =E13-D13 -> 0
A14: 10 | C14: DAUDET | D14: 0 | E14: 0 | K14: =E14-D14 -> 0
A15: 11 | C15: DAUDET | D15: 0 | E15: 0 | K15: =E15-D15 -> 0
A16: 12 | C16: DAUDET | D16: 0 | E16: 0 | K16: =E16-D16 -> 0 | M16: Nb pièce produite (fausse et bonne) | N16: Nombre piéce fausse | O16: nombre piéce bonne | P16: taux qualité | Q16: Tcy moyen
A17: 13 | C17: DAUDET | D17: 0 | E17: 0 | K17: =E17-D17 -> 0 | M17: =COUNTA(J5:J45) -> 2 | N17: =COUNTIF(J5:J46,"non") -> 1 | O17: =COUNTIF(J5:J45,"oui") -> 1 | P17: =(M17-N17)/M17 -> 0.5 | Q17: =AVERAGEIF(K$5:K$200,"<>0") -> 0.034027778
A18: 14 | C18: DAUDET | D18: 0 | E18: 0 | K18: =E18-D18 -> 0
A19: 15 | C19: DAUDET | D19: 0 | E19: 0 | K19: =E19-D19 -> 0
A20: 16 | C20: DAUDET | D20: 0 | E20: 0 | K20: =E20-D20 -> 0
A21: 17 | C21: DAUDET | D21: 0 | E21: 0 | K21: =E21-D21 -> 0
A22: 18 | C22: DAUDET | D22: 0 | E22: 0 | K22: =E22-D22 -> 0
